<?xml version="1.0"?>
<robot name="robot_name">

    <link name="base_link">
        
    </link>

    <link name="chassis_link">
        <inertial>
            <origin xyz="0.0 0.0 0.0" rpy="0.0 0.0 0.0"/>
            <mass value="1.0"/>
            <inertia ixx="0.1" ixy="0.0" ixz="0.0" iyy="0.1" iyz="0.0" izz="0.1"/>
        </inertial>
        <visual name="">
            <origin xyz="0.0 0.0 0.0" rpy="0.0 0.0 0.0"/>
            <geometry>
                <box size="1.2 0.7 0.5"/>
            </geometry>
            <material name="">
                <color rgba="0.7 0.0 0.0 1.0"/>
            </material>
        </visual>
        <collision>
            <origin xyz="0.0 0.0 0.0" rpy="0.0 0.0 0.0"/>
            <geometry>
                <box size="1.0 0.5 0.2"/>
            </geometry>
        </collision>
    </link>

    <gazebo reference = "chassis_link">
        <material>Gazebo/Black</material>
    </gazebo>

    <joint name="chassis_joint" type="fixed">
        <parent link="base_link"/>
        <child link="chassis_link"/>
        <origin xyz="-0.1 0 0"/>
    </joint>

    <link name="front_left_wheel">
        <inertial>
            <origin xyz="0.0 0.0 0.0" rpy="0.0 0.0 0.0"/>
            <mass value="0.5"/>
            <inertia ixx="0.05" ixy="0.0" ixz="0.0" iyy="0.05" iyz="0.0" izz="0.05"/>
        </inertial>
        <visual name="">
            <origin xyz="0.0 0.0 0.0" rpy="1.57 0.0 0.0"/>
            <geometry>
                <cylinder radius="0.3" length="0.3"/>
            </geometry>
            <material name="">
                <color rgba="0.0 1.0 0.0 1.0"/>
            </material>
        </visual>
        <collision>
            <origin xyz="0.0 0.0 0.0" rpy="1.57 0.0 0.0"/>
            <geometry>
                <cylinder radius="0.3" length="0.3"/>
            </geometry>
        </collision>
    </link>

    <gazebo reference = "front_left_wheel">
        <material>Gazebo/Red</material>
    </gazebo>

    <joint name="front_left_wheel_joint" type="continuous">
        <parent link="chassis_link"/>
        <child link="front_left_wheel"/>
        <axis xyz="0 1 0"/>
        <origin xyz="0.5 0.5 0.0" rpy="0 0 0"/>
    </joint>

    <link name="front_right_wheel">
        <inertial>
            <origin xyz="0.0 0.0 0.0" rpy="0.0 0.0 0.0"/>
            <mass value="0.5"/>
            <inertia ixx="0.05" ixy="0.0" ixz="0.0" iyy="0.05" iyz="0.0" izz="0.05"/>
        </inertial>
        <visual name="">
            <origin xyz="0.0 0.0 0.0" rpy="1.57 0.0 0.0"/>
            <geometry>
                <cylinder radius="0.3" length="0.3"/>
            </geometry>
            <material name="">
                <color rgba="0.0 1.0 0.0 1.0"/>
            </material>
        </visual>
        <collision>
            <origin xyz="0.0 0.0 0.0" rpy="1.57 0.0 0.0"/>
            <geometry>
                <cylinder radius="0.3" length="0.3"/>
            </geometry>
        </collision>
    </link>

    <gazebo reference = "front_right_wheel">
        <material>Gazebo/Red</material>
    </gazebo>

    <joint name="front_right_wheel_joint" type="continuous">
        <parent link="chassis_link"/>
        <child link="front_right_wheel"/>
        <axis xyz="0 1 0"/>
        <origin xyz="0.5 -0.5 0.0" rpy="0 0 0"/>
    </joint>

    <link name="back_left_wheel">
        <inertial>
            <origin xyz="0.0 0.0 0.0" rpy="0.0 0.0 0.0"/>
            <mass value="0.5"/>
            <inertia ixx="0.05" ixy="0.0" ixz="0.0" iyy="0.05" iyz="0.0" izz="0.05"/>
        </inertial>
        <visual name="">
            <origin xyz="0.0 0.0 0.0" rpy="1.57 0.0 0.0"/>
            <geometry>
                <cylinder radius="0.3" length="0.3"/>
            </geometry>
            <material name="">
                <color rgba="0.0 1.0 0.0 1.0"/>
            </material>
        </visual>
        <collision>
            <origin xyz="0.0 0.0 0.0" rpy="1.57 0.0 0.0"/>
            <geometry>
                <cylinder radius="0.3" length="0.3"/>
            </geometry>
        </collision>
    </link>

    <gazebo reference = "back_left_wheel">
        <material>Gazebo/Red</material>
    </gazebo>

    <joint name="back_left_wheel_joint" type="continuous">
        <parent link="chassis_link"/>
        <child link="back_left_wheel"/>
        <axis xyz="0 1 0"/>
        <origin xyz="-0.5 0.5 0.0" rpy="0 0 0"/>
    </joint>

    <link name="back_right_wheel">
        <inertial>
            <origin xyz="0.0 0.0 0.0" rpy="0.0 0.0 0.0"/>
            <mass value="0.5"/>
            <inertia ixx="0.05" ixy="0.0" ixz="0.0" iyy="0.05" iyz="0.0" izz="0.05"/>
        </inertial>
        <visual name="">
            <origin xyz="0.0 0.0 0.0" rpy="1.57 0.0 0.0"/>
            <geometry>
                <cylinder radius="0.3" length="0.3"/>
            </geometry>
            <material name="">
                <color rgba="0.0 1.0 0.0 1.0"/>
            </material>
        </visual>
        <collision>
            <origin xyz="0.0 0.0 0.0" rpy="1.57 0.0 0.0"/>
            <geometry>
                <cylinder radius="0.3" length="0.3"/>
            </geometry>
        </collision>
    </link>

    <gazebo reference = "back_right_wheel">
        <material>Gazebo/Red</material>
    </gazebo>

    <joint name="back_right_wheel_joint" type="continuous">
        <parent link="chassis_link"/>
        <child link="back_right_wheel"/>
        <axis xyz="0 1 0"/>
        <origin xyz="-0.5 -0.5 0.0" rpy="0 0 0"/>
    </joint>
</robot>
